Workbook
Name Роздільник_Відділ: #N/A
Name Роздільник_Діапазон_стажу: #N/A

Sheet Завдання 2
B2: Завдання. (у першому рядку приклад для заповнення)
B3: 1. Перенесіть у стовпці D та E імена та по батькові співробітників зі стовпця C, у стовпці C залиште лише прізвище. | K3: Таблиця 2.
B4: 2. У стовпці G вкажіть гендерну приналежність працівників. | J4: № | K4: Показник | O4: Значення
B5: 3. У стовпці H вкажіть вік працівників на дату прийому на роботу (кількість повних років). | J5: 1 | K5: Кількість працюючих на дату звіту | O5: =COUNTBLANK(K18:K117) -> 39
B6: 4. У стовпці I вкажіть, чи досяг працівник пенсійного віку на момент прийому на роботу, якщо пенсійний вік становить 60 років. | J6: 2 | K6: Кількість звільнених на дату звіту | O6: =COUNT(K18:K117) -> 61
J7: 3 | K7: Кількість звільнених на 01.01.2009 | O7: =COUNTIF(K18:K117,"<39814") -> 3
B8: 5. Заповніть стовпець L; якщо в стовпці K дата звільнення відсутня, то розрахуйте стаж на дату звіту (клітинка F14). | J8: 4 | K8: Середній вік звільнених | O8: {=AVERAGE(IF(K18:K117<>"",DATEDIF(F18:F117,K18:K117,"Y"),""))} -> 44.704918
B9: 6. Налаштуйте сортування Таблиці 1 за Відділом, Прізвищем. | J9: 5 | K9: Працівників якої статі більше звільнили | O9: =IF(COUNTIFS(K18:K117,">0",G18:G117,"чоловіча")>COUNTIFS(K18:K117,">0",G18:G117,";жіноча"),"чоловічої", IF(COUNTIFS(K18:K117,">0",G18:G117,"чоловіча")<COUNTIFS(K18:K117,">0",G18:G117,"жіноча"),"жіночої","одинаково")) -> чоловічої
B10: 7. Додайте стовпець "Відділ", в який додайте відповідні значення для кожного співробітника з аркуша "Відділи". | J10: 6 | K10: Кількість співробітників із прізвищем, яке починається на "Р" | O10: =COUNTIF(C18:C117,"Р*") -> 4
B11: 8. Заповніть в Таблиці 2 стовпець "Значення" за допомогою формул. | J11: 7 | K11: Кількість причин звільнення | O11: =COUNTA(_xlfn.UNIQUE(M18:M117))-1 -> 6
J12: 8 | K12: Найчастіша причина звільнення | O12: {=INDEX($R$18:$R$23,MATCH(MAX(COUNTIF(M18:M117,$R$18:$R$23)),COUNTIF(M18:M117,$R$18:$R$23),0))} -> за власним бажанням
C14: Таблиця 1. Звіт про стаж роботи співробітників, в тому числі звільнених на | F14: 44927
B16: № | C16: ПІБ співробітника | F16: Дата народження | G16: Стать | H16: Вік на момент прийому на роботу | I16: Пенсійний вік | J16: Дата прийому на роботу | K16: Дата звільнення | L16: Стаж | M16: Причина звільнення | N16: Відділ | O16: вік звільнених | P16: перевірка
C17: Прізвище | D17: Ім'я | E17: По батькові | P17: =AVERAGE(O18:O117) -> 44.704918 | Q17: перевірка | R17: Причини звільнення
B18: 99 | C18: Величко | D18: Самійло | E18: Васильович | F18: 23575 | G18: =IF(RIGHT(E18,1)="ч","чоловіча","жіноча") -> чоловіча | H18: =ROUNDDOWN((J18-F18)/365.25,0) -> 42 | I18: =IF(H18>=60,"так","ні") -> ні | J18: 39161 | L18: =IFERROR(IF(DATEDIF(J18,K18,"Y")=0,DATEDIF(J18,K18,"M")&"м."&DATEDIF(J18,K18,"MD")&"д.", DATEDIF(J18,K18,"Y")&"р."&DATEDIF(J18,K18,"YM")&"м."&DATEDIF(J18,K18,"MD")&"д."), IF(DATEDIF(J18,$F$14,"Y")=0,DATEDIF(J18,$F$14,"M")&"м."&DATEDIF(J18,$F$14,"MD")&"д.", DATEDIF(J18,$F$14,"Y")&"р."&DATEDIF(J18,$F$14,"YM")&"м."&DATEDIF(J18,$F$14,"MD")&"д.")) -> 15р.9м.12д. | N18: =VLOOKUP(_xlfn.CONCAT(C18," ",D18," ",E18),Відділи!$B$2:$C$101,2,0) -> Бухгалтерія | O18: =IFERROR(DATEDIF(F18,K18,"Y"),"") | Q18: {=COUNTIF(M18:M117,$R$18:$R$23)} -> 25 | R18: за власним бажанням
B19: 48 | C19: Гончаренко | D19: Ніна | E19: Іванівна | F19: 28873 | G19: =IF(RIGHT(E19,1)="ч","чоловіча","жіноча") -> жіноча | H19: =ROUNDDOWN((J19-F19)/365.25,0) -> 34 | I19: =IF(H19>=60,"так","ні") -> ні | J19: 41402 | L19: =IFERROR(IF(DATEDIF(J19,K19,"Y")=0,DATEDIF(J19,K19,"M")&"м."&DATEDIF(J19,K19,"MD")&"д.", DATEDIF(J19,K19,"Y")&"р."&DATEDIF(J19,K19,"YM")&"м."&DATEDIF(J19,K19,"MD")&"д."), IF(DATEDIF(J19,$F$14,"Y")=0,DATEDIF(J19,$F$14,"M")&"м."&DATEDIF(J19,$F$14,"MD")&"д.", DATEDIF(J19,$F$14,"Y")&"р."&DATEDIF(J19,$F$14,"YM")&"м."&DATEDIF(J19,$F$14,"MD")&"д.")) -> 9р.7м.24д. | N19: =VLOOKUP(_xlfn.CONCAT(C19," ",D19," ",E19),Відділи!$B$2:$C$101,2,0) -> Бухгалтерія | O19: =IFERROR(DATEDIF(F19,K19,"Y"),"") | Q19: 2 | R19: порушення трудового договору | T19: числова дата 01,01,2009
B20: 13 | C20: Іванова | D20: Антоніна | E20: Миколаївна | F20: 22028 | G20: =IF(RIGHT(E20,1)="ч","чоловіча","жіноча") -> жіноча | H20: =ROUNDDOWN((J20-F20)/365.25,0) -> 54 | I20: =IF(H20>=60,"так","ні") -> ні | J20: 41977 | L20: =IFERROR(IF(DATEDIF(J20,K20,"Y")=0,DATEDIF(J20,K20,"M")&"м."&DATEDIF(J20,K20,"MD")&"д.", DATEDIF(J20,K20,"Y")&"р."&DATEDIF(J20,K20,"YM")&"м."&DATEDIF(J20,K20,"MD")&"д."), IF(DATEDIF(J20,$F$14,"Y")=0,DATEDIF(J20,$F$14,"M")&"м."&DATEDIF(J20,$F$14,"MD")&"д.", DATEDIF(J20,$F$14,"Y")&"р."&DATEDIF(J20,$F$14,"YM")&"м."&DATEDIF(J20,$F$14,"MD")&"д.")) -> 8р.0м.28д. | N20: =VLOOKUP(_xlfn.CONCAT(C20," ",D20," ",E20),Відділи!$B$2:$C$101,2,0) -> Бухгалтерія | O20: =IFERROR(DATEDIF(F20,K20,"Y"),"") | Q20: 13 | R20: за згодою сторін | T20: 39814
B21: 9 | C21: Коваль | D21: Олександр | E21: Іванович | F21: 24302 | G21: =IF(RIGHT(E21,1)="ч","чоловіча","жіноча") -> чоловіча | H21: =ROUNDDOWN((J21-F21)/365.25,0) -> 46 | I21: =IF(H21>=60,"так","ні") -> ні | J21: 41434 | L21: =IFERROR(IF(DATEDIF(J21,K21,"Y")=0,DATEDIF(J21,K21,"M")&"м."&DATEDIF(J21,K21,"MD")&"д.", DATEDIF(J21,K21,"Y")&"р."&DATEDIF(J21,K21,"YM")&"м."&DATEDIF(J21,K21,"MD")&"д."), IF(DATEDIF(J21,$F$14,"Y")=0,DATEDIF(J21,$F$14,"M")&"м."&DATEDIF(J21,$F$14,"MD")&"д.", DATEDIF(J21,$F$14,"Y")&"р."&DATEDIF(J21,$F$14,"YM")&"м."&DATEDIF(J21,$F$14,"MD")&"д.")) -> 9р.6м.23д. | N21: =VLOOKUP(_xlfn.CONCAT(C21," ",D21," ",E21),Відділи!$B$2:$C$101,2,0) -> Бухгалтерія | O21: =IFERROR(DATEDIF(F21,K21,"Y"),"") | Q21: 4 | R21: завершення трудового договору
B22: 62 | C22: Ковтун | D22: Ілля | E22: Юрійович | F22: 17062 | G22: =IF(RIGHT(E22,1)="ч","чоловіча","жіноча") -> чоловіча | H22: =ROUNDDOWN((J22-F22)/365.25,0) -> 63 | I22: =IF(H22>=60,"так","ні") -> так | J22: 40409 | L22: =IFERROR(IF(DATEDIF(J22,K22,"Y")=0,DATEDIF(J22,K22,"M")&"м."&DATEDIF(J22,K22,"MD")&"д.", DATEDIF(J22,K22,"Y")&"р."&DATEDIF(J22,K22,"YM")&"м."&DATEDIF(J22,K22,"MD")&"д."), IF(DATEDIF(J22,$F$14,"Y")=0,DATEDIF(J22,$F$14,"M")&"м."&DATEDIF(J22,$F$14,"MD")&"д.", DATEDIF(J22,$F$14,"Y")&"р."&DATEDIF(J22,$F$14,"YM")&"м."&DATEDIF(J22,$F$14,"MD")&"д.")) -> 12р.4м.13д. | N22: =VLOOKUP(_xlfn.CONCAT(C22," ",D22," ",E22),Відділи!$B$2:$C$101,2,0) -> Бухгалтерія | O22: =IFERROR(DATEDIF(F22,K22,"Y"),"") | Q22: 12 | R22: не відповідність
B23: 46 | C23: Литвиненко | D23: Марія | E23: Іванівна | F23: 23927 | G23: =IF(RIGHT(E23,1)="ч","чоловіча","жіноча") -> жіноча | H23: =ROUNDDOWN((J23-F23)/365.25,0) -> 44 | I23: =IF(H23>=60,"так","ні") -> ні | J23: 40122 | L23: =IFERROR(IF(DATEDIF(J23,K23,"Y")=0,DATEDIF(J23,K23,"M")&"м."&DATEDIF(J23,K23,"MD")&"д.", DATEDIF(J23,K23,"Y")&"р."&DATEDIF(J23,K23,"YM")&"м."&DATEDIF(J23,K23,"MD")&"д."), IF(DATEDIF(J23,$F$14,"Y")=0,DATEDIF(J23,$F$14,"M")&"м."&DATEDIF(J23,$F$14,"MD")&"д.", DATEDIF(J23,$F$14,"Y")&"р."&DATEDIF(J23,$F$14,"YM")&"м."&DATEDIF(J23,$F$14,"MD")&"д.")) -> 13р.1м.27д. | N23: =VLOOKUP(_xlfn.CONCAT(C23," ",D23," ",E23),Відділи!$B$2:$C$101,2,0) -> Бухгалтерія | O23: =IFERROR(DATEDIF(F23,K23,"Y"),"") | Q23: 5 | R23: скорочення штату
B24: 77 | C24: Макаренко | D24: Антон | E24: Семенович | F24: 33375 | G24: =IF(RIGHT(E24,1)="ч","чоловіча","жіноча") -> чоловіча | H24: =ROUNDDOWN((J24-F24)/365.25,0) -> 21 | I24: =IF(H24>=60,"так","ні") -> ні | J24: 41178 | K24: 43312 | L24: =IFERROR(IF(DATEDIF(J24,K24,"Y")=0,DATEDIF(J24,K24,"M")&"м."&DATEDIF(J24,K24,"MD")&"д.", DATEDIF(J24,K24,"Y")&"р."&DATEDIF(J24,K24,"YM")&"м."&DATEDIF(J24,K24,"MD")&"д."), IF(DATEDIF(J24,$F$14,"Y")=0,DATEDIF(J24,$F$14,"M")&"м."&DATEDIF(J24,$F$14,"MD")&"д.", DATEDIF(J24,$F$14,"Y")&"р."&DATEDIF(J24,$F$14,"YM")&"м."&DATEDIF(J24,$F$14,"MD")&"д.")) -> 5р.10м.5д. | M24: за власним бажанням | N24: =VLOOKUP(_xlfn.CONCAT(C24," ",D24," ",E24),Відділи!$B$2:$C$101,2,0) -> Бухгалтерія | O24: =IFERROR(DATEDIF(F24,K24,"Y"),"") -> 27
B25: 84 | C25: Марчук | D25: Євген | E25: Кирилович | F25: 29020 | G25: =IF(RIGHT(E25,1)="ч","чоловіча","жіноча") -> чоловіча | H25: =ROUNDDOWN((J25-F25)/365.25,0) -> 32 | I25: =IF(H25>=60,"так","ні") -> ні | J25: 40825 | K25: 42579 | L25: =IFERROR(IF(DATEDIF(J25,K25,"Y")=0,DATEDIF(J25,K25,"M")&"м."&DATEDIF(J25,K25,"MD")&"д.", DATEDIF(J25,K25,"Y")&"р."&DATEDIF(J25,K25,"YM")&"м."&DATEDIF(J25,K25,"MD")&"д."), IF(DATEDIF(J25,$F$14,"Y")=0,DATEDIF(J25,$F$14,"M")&"м."&DATEDIF(J25,$F$14,"MD")&"д.", DATEDIF(J25,$F$14,"Y")&"р."&DATEDIF(J25,$F$14,"YM")&"м."&DATEDIF(J25,$F$14,"MD")&"д.")) -> 4р.9м.19д. | M25: за власним бажанням | N25: =VLOOKUP(_xlfn.CONCAT(C25," ",D25," ",E25),Відділи!$B$2:$C$101,2,0) -> Бухгалтерія | O25: =IFERROR(DATEDIF(F25,K25,"Y"),"") -> 37
B26: 1 | C26: Мельник | D26: Андрій | E26: Андрійович | F26: 21956 | G26: чоловіча | H26: 53 | I26: ні | J26: 41530 | L26: 9р.3м.19д. | N26: =VLOOKUP(_xlfn.CONCAT(C26," ",D26," ",E26),Відділи!$B$2:$C$101,2,0) -> Бухгалтерія | O26: =IFERROR(DATEDIF(F26,K26,"Y"),"")
B27: 36 | C27: Мельничук | D27: Людмила | E27: Олександрівна | F27: 24224 | G27: =IF(RIGHT(E27,1)="ч","чоловіча","жіноча") -> жіноча | H27: =ROUNDDOWN((J27-F27)/365.25,0) -> 45 | I27: =IF(H27>=60,"так","ні") -> ні | J27: 40953 | K27: 43891 | L27: =IFERROR(IF(DATEDIF(J27,K27,"Y")=0,DATEDIF(J27,K27,"M")&"м."&DATEDIF(J27,K27,"MD")&"д.", DATEDIF(J27,K27,"Y")&"р."&DATEDIF(J27,K27,"YM")&"м."&DATEDIF(J27,K27,"MD")&"д."), IF(DATEDIF(J27,$F$14,"Y")=0,DATEDIF(J27,$F$14,"M")&"м."&DATEDIF(J27,$F$14,"MD")&"д.", DATEDIF(J27,$F$14,"Y")&"р."&DATEDIF(J27,$F$14,"YM")&"м."&DATEDIF(J27,$F$14,"MD")&"д.")) -> 8р.0м.16д. | M27: порушення трудового договору | N27: =VLOOKUP(_xlfn.CONCAT(C27," ",D27," ",E27),Відділи!$B$2:$C$101,2,0) -> Бухгалтерія | O27: =IFERROR(DATEDIF(F27,K27,"Y"),"") -> 53
B28: 19 | C28: Мороз | D28: Олександр | E28: Олександрович | F28: 21196 | G28: =IF(RIGHT(E28,1)="ч","чоловіча","жіноча") -> чоловіча | H28: =ROUNDDOWN((J28-F28)/365.25,0) -> 54 | I28: =IF(H28>=60,"так","ні") -> ні | J28: 40921 | K28: 44494 | L28: =IFERROR(IF(DATEDIF(J28,K28,"Y")=0,DATEDIF(J28,K28,"M")&"м."&DATEDIF(J28,K28,"MD")&"д.", DATEDIF(J28,K28,"Y")&"р."&DATEDIF(J28,K28,"YM")&"м."&DATEDIF(J28,K28,"MD")&"д."), IF(DATEDIF(J28,$F$14,"Y")=0,DATEDIF(J28,$F$14,"M")&"м."&DATEDIF(J28,$F$14,"MD")&"д.", DATEDIF(J28,$F$14,"Y")&"р."&DATEDIF(J28,$F$14,"YM")&"м."&DATEDIF(J28,$F$14,"MD")&"д.")) -> 9р.9м.12д. | M28: за згодою сторін | N28: =VLOOKUP(_xlfn.CONCAT(C28," ",D28," ",E28),Відділи!$B$2:$C$101,2,0) -> Бухгалтерія | O28: =IFERROR(DATEDIF(F28,K28,"Y"),"") -> 63
B29: 55 | C29: Назаренко | D29: Сергій | E29: Юрійович | F29: 30614 | G29: =IF(RIGHT(E29,1)="ч","чоловіча","жіноча") -> чоловіча | H29: =ROUNDDOWN((J29-F29)/365.25,0) -> 29 | I29: =IF(H29>=60,"так","ні") -> ні | J29: 41370 | K29: 41645 | L29: =IFERROR(IF(DATEDIF(J29,K29,"Y")=0,DATEDIF(J29,K29,"M")&"м."&DATEDIF(J29,K29,"MD")&"д.", DATEDIF(J29,K29,"Y")&"р."&DATEDIF(J29,K29,"YM")&"м."&DATEDIF(J29,K29,"MD")&"д."), IF(DATEDIF(J29,$F$14,"Y")=0,DATEDIF(J29,$F$14,"M")&"м."&DATEDIF(J29,$F$14,"MD")&"д.", DATEDIF(J29,$F$14,"Y")&"р."&DATEDIF(J29,$F$14,"YM")&"м."&DATEDIF(J29,$F$14,"MD")&"д.")) -> 9м.0д. | M29: за власним бажанням | N29: =VLOOKUP(_xlfn.CONCAT(C29," ",D29," ",E29),Відділи!$B$2:$C$101,2,0) -> Бухгалтерія | O29: =IFERROR(DATEDIF(F29,K29,"Y"),"") -> 30
B30: 44 | C30: Павлюк | D30: Павло | E30: Михнович | F30: 15594 | G30: =IF(RIGHT(E30,1)="ч","чоловіча","жіноча") -> чоловіча | H30: =ROUNDDOWN((J30-F30)/365.25,0) -> 70 | I30: =IF(H30>=60,"так","ні") -> так | J30: 41466 | L30: =IFERROR(IF(DATEDIF(J30,K30,"Y")=0,DATEDIF(J30,K30,"M")&"м."&DATEDIF(J30,K30,"MD")&"д.", DATEDIF(J30,K30,"Y")&"р."&DATEDIF(J30,K30,"YM")&"м."&DATEDIF(J30,K30,"MD")&"д."), IF(DATEDIF(J30,$F$14,"Y")=0,DATEDIF(J30,$F$14,"M")&"м."&DATEDIF(J30,$F$14,"MD")&"д.", DATEDIF(J30,$F$14,"Y")&"р."&DATEDIF(J30,$F$14,"YM")&"м."&DATEDIF(J30,$F$14,"MD")&"д.")) -> 9р.5м.21д. | N30: =VLOOKUP(_xlfn.CONCAT(C30," ",D30," ",E30),Відділи!$B$2:$C$101,2,0) -> Бухгалтерія | O30: =IFERROR(DATEDIF(F30,K30,"Y"),"")
B31: 18 | C31: Руденко | D31: Бела | E31: Андріївна | F31: 34241 | G31: =IF(RIGHT(E31,1)="ч","чоловіча","жіноча") -> жіноча | H31: =ROUNDDOWN((J31-F31)/365.25,0) -> 17 | I31: =IF(H31>=60,"так","ні") -> ні | J31: 40601 | K31: 43800 | L31: =IFERROR(IF(DATEDIF(J31,K31,"Y")=0,DATEDIF(J31,K31,"M")&"м."&DATEDIF(J31,K31,"MD")&"д.", DATEDIF(J31,K31,"Y")&"р."&DATEDIF(J31,K31,"YM")&"м."&DATEDIF(J31,K31,"MD")&"д."), IF(DATEDIF(J31,$F$14,"Y")=0,DATEDIF(J31,$F$14,"M")&"м."&DATEDIF(J31,$F$14,"MD")&"д.", DATEDIF(J31,$F$14,"Y")&"р."&DATEDIF(J31,$F$14,"YM")&"м."&DATEDIF(J31,$F$14,"MD")&"д.")) -> 8р.9м.4д. | M31: завершення трудового договору | N31: =VLOOKUP(_xlfn.CONCAT(C31," ",D31," ",E31),Відділи!$B$2:$C$101,2,0) -> Бухгалтерія | O31: =IFERROR(DATEDIF(F31,K31,"Y"),"") -> 26
B32: 97 | C32: Шульга | D32: Анастасія | E32: Олександрівна | F32: 24140 | G32: =IF(RIGHT(E32,1)="ч","чоловіча","жіноча") -> жіноча | H32: =ROUNDDOWN((J32-F32)/365.25,0) -> 45 | I32: =IF(H32>=60,"так","ні") -> ні | J32: 40761 | L32: =IFERROR(IF(DATEDIF(J32,K32,"Y")=0,DATEDIF(J32,K32,"M")&"м."&DATEDIF(J32,K32,"MD")&"д.", DATEDIF(J32,K32,"Y")&"р."&DATEDIF(J32,K32,"YM")&"м."&DATEDIF(J32,K32,"MD")&"д."), IF(DATEDIF(J32,$F$14,"Y")=0,DATEDIF(J32,$F$14,"M")&"м."&DATEDIF(J32,$F$14,"MD")&"д.", DATEDIF(J32,$F$14,"Y")&"р."&DATEDIF(J32,$F$14,"YM")&"м."&DATEDIF(J32,$F$14,"MD")&"д.")) -> 11р.4м.26д. | N32: =VLOOKUP(_xlfn.CONCAT(C32," ",D32," ",E32),Відділи!$B$2:$C$101,2,0) -> Бухгалтерія | O32: =IFERROR(DATEDIF(F32,K32,"Y"),"")
B33: 40 | C33: Юрченко | D33: Анатолій | E33: Петрович | F33: 24595 | G33: =IF(RIGHT(E33,1)="ч","чоловіча","жіноча") -> чоловіча | H33: =ROUNDDOWN((J33-F33)/365.25,0) -> 44 | I33: =IF(H33>=60,"так","ні") -> ні | J33: 40889 | K33: 44112 | L33: =IFERROR(IF(DATEDIF(J33,K33,"Y")=0,DATEDIF(J33,K33,"M")&"м."&DATEDIF(J33,K33,"MD")&"д.", DATEDIF(J33,K33,"Y")&"р."&DATEDIF(J33,K33,"YM")&"м."&DATEDIF(J33,K33,"MD")&"д."), IF(DATEDIF(J33,$F$14,"Y")=0,DATEDIF(J33,$F$14,"M")&"м."&DATEDIF(J33,$F$14,"MD")&"д.", DATEDIF(J33,$F$14,"Y")&"р."&DATEDIF(J33,$F$14,"YM")&"м."&DATEDIF(J33,$F$14,"MD")&"д.")) -> 8р.9м.26д. | M33: завершення трудового договору | N33: =VLOOKUP(_xlfn.CONCAT(C33," ",D33," ",E33),Відділи!$B$2:$C$101,2,0) -> Бухгалтерія | O33: =IFERROR(DATEDIF(F33,K33,"Y"),"") -> 53
B34: 5 | C34: Бойко | D34: Юрій | E34: Анатолійович | F34: 32924 | G34: =IF(RIGHT(E34,1)="ч","чоловіча","жіноча") -> чоловіча | H34: =ROUNDDOWN((J34-F34)/365.25,0) -> 19 | I34: =IF(H34>=60,"так","ні") -> ні | J34: 40058 | L34: =IFERROR(IF(DATEDIF(J34,K34,"Y")=0,DATEDIF(J34,K34,"M")&"м."&DATEDIF(J34,K34,"MD")&"д.", DATEDIF(J34,K34,"Y")&"р."&DATEDIF(J34,K34,"YM")&"м."&DATEDIF(J34,K34,"MD")&"д."), IF(DATEDIF(J34,$F$14,"Y")=0,DATEDIF(J34,$F$14,"M")&"м."&DATEDIF(J34,$F$14,"MD")&"д.", DATEDIF(J34,$F$14,"Y")&"р."&DATEDIF(J34,$F$14,"YM")&"м."&DATEDIF(J34,$F$14,"MD")&"д.")) -> 13р.3м.30д. | N34: =VLOOKUP(_xlfn.CONCAT(C34," ",D34," ",E34),Відділи!$B$2:$C$101,2,0) -> Відділ збуту | O34: =IFERROR(DATEDIF(F34,K34,"Y"),"")
B35: 71 | C35: Вовк | D35: Федір | E35: Кіндратович | F35: 27582 | G35: =IF(RIGHT(E35,1)="ч","чоловіча","жіноча") -> чоловіча | H35: =ROUNDDOWN((J35-F35)/365.25,0) -> 38 | I35: =IF(H35>=60,"так","ні") -> ні | J35: 41594 | K35: 41773 | L35: =IFERROR(IF(DATEDIF(J35,K35,"Y")=0,DATEDIF(J35,K35,"M")&"м."&DATEDIF(J35,K35,"MD")&"д.", DATEDIF(J35,K35,"Y")&"р."&DATEDIF(J35,K35,"YM")&"м."&DATEDIF(J35,K35,"MD")&"д."), IF(DATEDIF(J35,$F$14,"Y")=0,DATEDIF(J35,$F$14,"M")&"м."&DATEDIF(J35,$F$14,"MD")&"д.", DATEDIF(J35,$F$14,"Y")&"р."&DATEDIF(J35,$F$14,"YM")&"м."&DATEDIF(J35,$F$14,"MD")&"д.")) -> 5м.28д. | M35: за згодою сторін | N35: =VLOOKUP(_xlfn.CONCAT(C35," ",D35," ",E35),Відділи!$B$2:$C$101,2,0) -> Відділ збуту | O35: =IFERROR(DATEDIF(F35,K35,"Y"),"") -> 38
B36: 94 | C36: Гордієнко | D36: Наталія | E36: Володимирівна | F36: 21594 | G36: =IF(RIGHT(E36,1)="ч","чоловіча","жіноча") -> жіноча | H36: =ROUNDDOWN((J36-F36)/365.25,0) -> 52 | I36: =IF(H36>=60,"так","ні") -> ні | J36: 40665 | K36: 42641 | L36: =IFERROR(IF(DATEDIF(J36,K36,"Y")=0,DATEDIF(J36,K36,"M")&"м."&DATEDIF(J36,K36,"MD")&"д.", DATEDIF(J36,K36,"Y")&"р."&DATEDIF(J36,K36,"YM")&"м."&DATEDIF(J36,K36,"MD")&"д."), IF(DATEDIF(J36,$F$14,"Y")=0,DATEDIF(J36,$F$14,"M")&"м."&DATEDIF(J36,$F$14,"MD")&"д.", DATEDIF(J36,$F$14,"Y")&"р."&DATEDIF(J36,$F$14,"YM")&"м."&DATEDIF(J36,$F$14,"MD")&"д.")) -> 5р.4м.26д. | M36: за згодою сторін | N36: =VLOOKUP(_xlfn.CONCAT(C36," ",D36," ",E36),Відділи!$B$2:$C$101,2,0) -> Відділ збуту | O36: =IFERROR(DATEDIF(F36,K36,"Y"),"") -> 57
B37: 100 | C37: Денисенко | D37: Лариса | E37: Володимирівна | F37: 24923 | G37: =IF(RIGHT(E37,1)="ч","чоловіча","жіноча") -> жіноча | H37: =ROUNDDOWN((J37-F37)/365.25,0) -> 40 | I37: =IF(H37>=60,"так","ні") -> ні | J37: 39546 | K37: 41320 | L37: =IFERROR(IF(DATEDIF(J37,K37,"Y")=0,DATEDIF(J37,K37,"M")&"м."&DATEDIF(J37,K37,"MD")&"д.", DATEDIF(J37,K37,"Y")&"р."&DATEDIF(J37,K37,"YM")&"м."&DATEDIF(J37,K37,"MD")&"д."), IF(DATEDIF(J37,$F$14,"Y")=0,DATEDIF(J37,$F$14,"M")&"м."&DATEDIF(J37,$F$14,"MD")&"д.", DATEDIF(J37,$F$14,"Y")&"р."&DATEDIF(J37,$F$14,"YM")&"м."&DATEDIF(J37,$F$14,"MD")&"д.")) -> 4р.10м.7д. | M37: за власним бажанням | N37: =VLOOKUP(_xlfn.CONCAT(C37," ",D37," ",E37),Відділи!$B$2:$C$101,2,0) -> Відділ збуту | O37: =IFERROR(DATEDIF(F37,K37,"Y"),"") -> 44
B38: 25 | C38: Іванов | D38: Микола | E38: Кузьмич | F38: 33931 | G38: =IF(RIGHT(E38,1)="ч","чоловіча","жіноча") -> чоловіча | H38: =ROUNDDOWN((J38-F38)/365.25,0) -> 21 | I38: =IF(H38>=60,"так","ні") -> ні | J38: 41690 | L38: =IFERROR(IF(DATEDIF(J38,K38,"Y")=0,DATEDIF(J38,K38,"M")&"м."&DATEDIF(J38,K38,"MD")&"д.", DATEDIF(J38,K38,"Y")&"р."&DATEDIF(J38,K38,"YM")&"м."&DATEDIF(J38,K38,"MD")&"д."), IF(DATEDIF(J38,$F$14,"Y")=0,DATEDIF(J38,$F$14,"M")&"м."&DATEDIF(J38,$F$14,"MD")&"д.", DATEDIF(J38,$F$14,"Y")&"р."&DATEDIF(J38,$F$14,"YM")&"м."&DATEDIF(J38,$F$14,"MD")&"д.")) -> 8р.10м.12д. | N38: =VLOOKUP(_xlfn.CONCAT(C38," ",D38," ",E38),Відділи!$B$2:$C$101,2,0) -> Відділ збуту | O38: =IFERROR(DATEDIF(F38,K38,"Y"),"")
B39: 74 | C39: Ковальова | D39: Ірина | E39: Федорівна | F39: 22060 | G39: =IF(RIGHT(E39,1)="ч","чоловіча","жіноча") -> жіноча | H39: =ROUNDDOWN((J39-F39)/365.25,0) -> 51 | I39: =IF(H39>=60,"так","ні") -> ні | J39: 40729 | L39: =IFERROR(IF(DATEDIF(J39,K39,"Y")=0,DATEDIF(J39,K39,"M")&"м."&DATEDIF(J39,K39,"MD")&"д.", DATEDIF(J39,K39,"Y")&"р."&DATEDIF(J39,K39,"YM")&"м."&DATEDIF(J39,K39,"MD")&"д."), IF(DATEDIF(J39,$F$14,"Y")=0,DATEDIF(J39,$F$14,"M")&"м."&DATEDIF(J39,$F$14,"MD")&"д.", DATEDIF(J39,$F$14,"Y")&"р."&DATEDIF(J39,$F$14,"YM")&"м."&DATEDIF(J39,$F$14,"MD")&"д.")) -> 11р.5м.27д. | N39: =VLOOKUP(_xlfn.CONCAT(C39," ",D39," ",E39),Відділи!$B$2:$C$101,2,0) -> Відділ збуту | O39: =IFERROR(DATEDIF(F39,K39,"Y"),"")
B40: 45 | C40: Кушнір | D40: Ігор | E40: Миколайович | F40: 26689 | G40: =IF(RIGHT(E40,1)="ч","чоловіча","жіноча") -> чоловіча | H40: =ROUNDDOWN((J40-F40)/365.25,0) -> 42 | I40: =IF(H40>=60,"так","ні") -> ні | J40: 42041 | L40: =IFERROR(IF(DATEDIF(J40,K40,"Y")=0,DATEDIF(J40,K40,"M")&"м."&DATEDIF(J40,K40,"MD")&"д.", DATEDIF(J40,K40,"Y")&"р."&DATEDIF(J40,K40,"YM")&"м."&DATEDIF(J40,K40,"MD")&"д."), IF(DATEDIF(J40,$F$14,"Y")=0,DATEDIF(J40,$F$14,"M")&"м."&DATEDIF(J40,$F$14,"MD")&"д.", DATEDIF(J40,$F$14,"Y")&"р."&DATEDIF(J40,$F$14,"YM")&"м."&DATEDIF(J40,$F$14,"MD")&"д.")) -> 7р.10м.26д. | N40: =VLOOKUP(_xlfn.CONCAT(C40," ",D40," ",E40),Відділи!$B$2:$C$101,2,0) -> Відділ збуту | O40: =IFERROR(DATEDIF(F40,K40,"Y"),"")
B41: 30 | C41: Левченко | D41: Юлія | E41: Андріївна | F41: 33220 | G41: =IF(RIGHT(E41,1)="ч","чоловіча","жіноча") -> жіноча | H41: =ROUNDDOWN((J41-F41)/365.25,0) -> 16 | I41: =IF(H41>=60,"так","ні") -> ні | J41: 39417 | L41: =IFERROR(IF(DATEDIF(J41,K41,"Y")=0,DATEDIF(J41,K41,"M")&"м."&DATEDIF(J41,K41,"MD")&"д.", DATEDIF(J41,K41,"Y")&"р."&DATEDIF(J41,K41,"YM")&"м."&DATEDIF(J41,K41,"MD")&"д."), IF(DATEDIF(J41,$F$14,"Y")=0,DATEDIF(J41,$F$14,"M")&"м."&DATEDIF(J41,$F$14,"MD")&"д.", DATEDIF(J41,$F$14,"Y")&"р."&DATEDIF(J41,$F$14,"YM")&"м."&DATEDIF(J41,$F$14,"MD")&"д.")) -> 15р.1м.0д. | N41: =VLOOKUP(_xlfn.CONCAT(C41," ",D41," ",E41),Відділи!$B$2:$C$101,2,0) -> Відділ збуту | O41: =IFERROR(DATEDIF(F41,K41,"Y"),"")
B42: 20 | C42: Лисенко | D42: Микола | E42: Віталійович | F42: 18715 | G42: =IF(RIGHT(E42,1)="ч","чоловіча","жіноча") -> чоловіча | H42: =ROUNDDOWN((J42-F42)/365.25,0) -> 64 | I42: =IF(H42>=60,"так","ні") -> так | J42: 42233 | L42: =IFERROR(IF(DATEDIF(J42,K42,"Y")=0,DATEDIF(J42,K42,"M")&"м."&DATEDIF(J42,K42,"MD")&"д.", DATEDIF(J42,K42,"Y")&"р."&DATEDIF(J42,K42,"YM")&"м."&DATEDIF(J42,K42,"MD")&"д."), IF(DATEDIF(J42,$F$14,"Y")=0,DATEDIF(J42,$F$14,"M")&"м."&DATEDIF(J42,$F$14,"MD")&"д.", DATEDIF(J42,$F$14,"Y")&"р."&DATEDIF(J42,$F$14,"YM")&"м."&DATEDIF(J42,$F$14,"MD")&"д.")) -> 7р.4м.15д. | N42: =VLOOKUP(_xlfn.CONCAT(C42," ",D42," ",E42),Відділи!$B$2:$C$101,2,0) -> Відділ збуту | O42: =IFERROR(DATEDIF(F42,K42,"Y"),"")
B43: 47 | C43: Мартинюк | D43: Адам | E43: Іванович | F43: 21994 | G43: =IF(RIGHT(E43,1)="ч","чоловіча","жіноча") -> чоловіча | H43: =ROUNDDOWN((J43-F43)/365.25,0) -> 47 | I43: =IF(H43>=60,"так","ні") -> ні | J43: 39257 | L43: =IFERROR(IF(DATEDIF(J43,K43,"Y")=0,DATEDIF(J43,K43,"M")&"м."&DATEDIF(J43,K43,"MD")&"д.", DATEDIF(J43,K43,"Y")&"р."&DATEDIF(J43,K43,"YM")&"м."&DATEDIF(J43,K43,"MD")&"д."), IF(DATEDIF(J43,$F$14,"Y")=0,DATEDIF(J43,$F$14,"M")&"м."&DATEDIF(J43,$F$14,"MD")&"д.", DATEDIF(J43,$F$14,"Y")&"р."&DATEDIF(J43,$F$14,"YM")&"м."&DATEDIF(J43,$F$14,"MD")&"д.")) -> 15р.6м.8д. | N43: =VLOOKUP(_xlfn.CONCAT(C43," ",D43," ",E43),Відділи!$B$2:$C$101,2,0) -> Відділ збуту | O43: =IFERROR(DATEDIF(F43,K43,"Y"),"")
...

Sheet Відділи
B1: Співробітник | C1: Відділ
B2: МЕЛЬНИК АНДРІЙ АНДРІЙОВИЧ | C2: Бухгалтерія
B3: ШЕВЧЕНКО ТАРАС ГРИГОРОВИЧ | C3: Юридичний відділ
B4: КОВАЛЕНКО АННА МИКОЛАЇВНА | C4: Фінансовий відділ
B5: БОНДАРЕНКО ОЛЕНА АНАТОЛІЇВНА | C5: Маркетинговий відділ
B6: БОЙКО ЮРІЙ АНАТОЛІЙОВИЧ | C6: Відділ збуту
B7: ТКАЧЕНКО ОЛЕКСАНДР МИКОЛАЙОВИЧ | C7: Господарський відділ
B8: КРАВЧЕНКО ВІКТОР АНДРІЙОВИЧ | C8: Дирекція
B9: КОВАЛЬЧУК КИРИЛО СЕРГІЙОВИЧ | C9: Відділ кадрів
B10: КОВАЛЬ ОЛЕКСАНДР ІВАНОВИЧ | C10: Бухгалтерія
B11: ОЛІЙНИК БОРИС ІЛЛІЧ | C11: Фінансовий відділ
B12: ШЕВЧУК СВЯТОСЛАВ ЮРІЙОВИЧ | C12: Господарський відділ
... B101: ДЕНИСЕНКО ЛАРИСА ВОЛОДИМИРІВНА | C101: Відділ збуту

Sheet Дані
E3: Показник | F3: Значення | K3: {=_xlfn.UNIQUE(L19:L118)} -> Бухгалтерія
E4: Кількість працюючих на дату звіту | F4: 39 | K4: Відділ збуту
E5: Кількість звільнених на дату звіту | F5: 61 | K5: Відділ кадрів
E6: Кількість звільнених на 01.01.2009 | F6: 3 | K6: Господарський відділ
E7: Середній вік звільнених | F7: 45 | K7: Дирекція
E8: Працівників якої статі більше звільнили | F8: чоловічої | K8: Маркетинговий відділ
E9: Кількість співробітників із прізвищем, яке починається на "Р" | F9: 4 | K9: Фінансовий відділ
E10: Кількість причин звільнення | F10: 6 | K10: Юридичний відділ
E11: Найчастіша причина звільнення | F11: за власним бажанням
E16: 44927 | O16: =MAX(Дані!$J$19:$J$118) -> 15
B18: № | C18: ПІБ | D18: Дата народження | E18: Стать | F18: Вік на момент прийому на роботу | G18: Пенсійний вік | H18: Дата прийому на роботу | I18: Дата звільнення | J18: Стаж | K18: Причина звільнення | L18: Відділ | M18: Вік звільнених | N18: Працює в даний момент | O18: Діапазон стажу
B19: 99 | C19: Величко Самійло Васильович | D19: 23575 | E19: чоловіча | F19: 42 | G19: ні | H19: 39161 | J19: 15 | L19: Бухгалтерія | N19: 1 | O19: 10-15р
B20: 48 | C20: Гончаренко Ніна Іванівна | D20: 28873 | E20: жіноча | F20: 34 | G20: ні | H20: 41402 | J20: 9 | L20: Бухгалтерія | N20: 1 | O20: 5-9р
B21: 13 | C21: Іванова Антоніна Миколаївна | D21: 22028 | E21: жіноча | F21: 54 | G21: ні | H21: 41977 | J21: 8 | L21: Бухгалтерія | N21: 1 | O21: 5-9р
B22: 9 | C22: Коваль Олександр Іванович | D22: 24302 | E22: чоловіча | F22: 46 | G22: ні | H22: 41434 | J22: 9 | L22: Бухгалтерія | N22: 1 | O22: 5-9р
B23: 62 | C23: Ковтун Ілля Юрійович | D23: 17062 | E23: чоловіча | F23: 63 | G23: так | H23: 40409 | J23: 12 | L23: Бухгалтерія | N23: 1 | O23: 10-15р
B24: 46 | C24: Литвиненко Марія Іванівна | D24: 23927 | E24: жіноча | F24: 44 | G24: ні | H24: 40122 | J24: 13 | L24: Бухгалтерія | N24: 1 | O24: 10-15р
B25: 77 | C25: Макаренко Антон Семенович | D25: 33375 | E25: чоловіча | F25: 21 | G25: ні | H25: 41178 | I25: 43312 | J25: 5 | K25: за власним бажанням | L25: Бухгалтерія | M25: 27 | N25: 0 | O25: 5-9р
B26: 84 | C26: Марчук Євген Кирилович | D26: 29020 | E26: чоловіча | F26: 32 | G26: ні | H26: 40825 | I26: 42579 | J26: 4 | K26: за власним бажанням | L26: Бухгалтерія | M26: 37 | N26: 0 | O26: 0-4р
B27: 1 | C27: Мельник Андрій Андрійович | D27: 21956 | E27: чоловіча | F27: 53 | G27: ні | H27: 41530 | J27: 9 | L27: Бухгалтерія | N27: 1 | O27: 5-9р
B28: 36 | C28: Мельничук Людмила Олександрівна | D28: 24224 | E28: жіноча | F28: 45 | G28: ні | H28: 40953 | I28: 43891 | J28: 8 | K28: порушення трудового договору | L28: Бухгалтерія | M28: 53 | N28: 0 | O28: 5-9р
B29: 19 | C29: Мороз Олександр Олександрович | D29: 21196 | E29: чоловіча | F29: 54 | G29: ні | H29: 40921 | I29: 44494 | J29: 9 | K29: за згодою сторін | L29: Бухгалтерія | M29: 63 | N29: 0 | O29: 5-9р
B30: 55 | C30: Назаренко Сергій Юрійович | D30: 30614 | E30: чоловіча | F30: 29 | G30: ні | H30: 41370 | I30: 41645 | J30: 0 | K30: за власним бажанням | L30: Бухгалтерія | M30: 30 | N30: 0 | O30: 0-4р
B31: 44 | C31: Павлюк Павло Михнович | D31: 15594 | E31: чоловіча | F31: 70 | G31: так | H31: 41466 | J31: 9 | L31: Бухгалтерія | N31: 1 | O31: 5-9р
B32: 18 | C32: Руденко Бела Андріївна | D32: 34241 | E32: жіноча | F32: 17 | G32: ні | H32: 40601 | I32: 43800 | J32: 8 | K32: завершення трудового договору | L32: Бухгалтерія | M32: 26 | N32: 0 | O32: 5-9р
B33: 97 | C33: Шульга Анастасія Олександрівна | D33: 24140 | E33: жіноча | F33: 45 | G33: ні | H33: 40761 | J33: 11 | L33: Бухгалтерія | N33: 1 | O33: 10-15р
B34: 40 | C34: Юрченко Анатолій Петрович | D34: 24595 | E34: чоловіча | F34: 44 | G34: ні | H34: 40889 | I34: 44112 | J34: 8 | K34: завершення трудового договору | L34: Бухгалтерія | M34: 53 | N34: 0 | O34: 5-9р
B35: 5 | C35: Бойко Юрій Анатолійович | D35: 32924 | E35: чоловіча | F35: 19 | G35: ні | H35: 40058 | J35: 13 | L35: Відділ збуту | N35: 1 | O35: 10-15р
B36: 71 | C36: Вовк Федір Кіндратович | D36: 27582 | E36: чоловіча | F36: 38 | G36: ні | H36: 41594 | I36: 41773 | J36: 0 | K36: за згодою сторін | L36: Відділ збуту | M36: 38 | N36: 0 | O36: 0-4р
B37: 94 | C37: Гордієнко Наталія Володимирівна | D37: 21594 | E37: жіноча | F37: 52 | G37: ні | H37: 40665 | I37: 42641 | J37: 5 | K37: за згодою сторін | L37: Відділ збуту | M37: 57 | N37: 0 | O37: 5-9р
B38: 100 | C38: Денисенко Лариса Володимирівна | D38: 24923 | E38: жіноча | F38: 40 | G38: ні | H38: 39546 | I38: 41320 | J38: 4 | K38: за власним бажанням | L38: Відділ збуту | M38: 44 | N38: 0 | O38: 0-4р
B39: 25 | C39: Іванов Микола Кузьмич | D39: 33931 | E39: чоловіча | F39: 21 | G39: ні | H39: 41690 | J39: 8 | L39: Відділ збуту | N39: 1 | O39: 5-9р
B40: 74 | C40: Ковальова Ірина Федорівна | D40: 22060 | E40: жіноча | F40: 51 | G40: ні | H40: 40729 | J40: 11 | L40: Відділ збуту | N40: 1 | O40: 10-15р
B41: 45 | C41: Кушнір Ігор Миколайович | D41: 26689 | E41: чоловіча | F41: 42 | G41: ні | H41: 42041 | J41: 7 | L41: Відділ збуту | N41: 1 | O41: 5-9р
B42: 30 | C42: Левченко Юлія Андріївна | D42: 33220 | E42: жіноча | F42: 16 | G42: ні | H42: 39417 | J42: 15 | L42: Відділ збуту | N42: 1 | O42: 10-15р
B43: 20 | C43: Лисенко Микола Віталійович | D43: 18715 | E43: чоловіча | F43: 64 | G43: так | H43: 42233 | J43: 7 | L43: Відділ збуту | N43: 1 | O43: 5-9р
B44: 47 | C44: Мартинюк Адам Іванович | D44: 21994 | E44: чоловіча | F44: 47 | G44: ні | H44: 39257 | J44: 15 | L44: Відділ збуту | N44: 1 | O44: 10-15р
B45: 65 | C45: Терещенко Михайло Іванович | D45: 26823 | E45: чоловіча | F45: 40 | G45: ні | H45: 41626 | I45: 42166 | J45: 1 | K45: за згодою сторін | L45: Відділ збуту | M45: 42 | N45: 0 | O45: 0-4р
B46: 14 | C46: Ткачук Геннадій Віталійович | D46: 31506 | E46: чоловіча | F46: 24 | G46: ні | H46: 40377 | I46: 42856 | J46: 6 | K46: за власним бажанням | L46: Відділ збуту | M46: 31 | N46: 0 | O46: 5-9р
B47: 76 | C47: Іщенко Михайло Олексійович | D47: 23629 | E47: чоловіча | F47: 50 | G47: ні | H47: 41945 | J47: 8 | L47: Відділ кадрів | N47: 1 | O47: 5-9р
...

Sheet Зведена таблиця
B1: Використовував не всі таблиці, текст не коригував, чисто розрахунково
A3: Позначки рядків | B3: Середнє з Вік на момент прийому на роботу | D3: Позначки рядків | E3: Кількість з Дата прийому на роботу | F3: Кількість з Дата звільнення | G3: Сума з Працює в даний момент
A4: Бухгалтерія | B4: 43.3125 | D4: Бухгалтерія | E4: 16 | F4: 7 | G4: 9
A5: Відділ збуту | B5: 37.833333 | D5: Відділ збуту | E5: 12 | F5: 5 | G5: 7
A6: Відділ кадрів | B6: 37.555556 | D6: Відділ кадрів | E6: 9 | F6: 6 | G6: 3
A7: Господарський відділ | B7: 43.4 | D7: Господарський відділ | E7: 10 | F7: 9 | G7: 1
A8: Дирекція | B8: 40.7 | D8: Дирекція | E8: 10 | F8: 9 | G8: 1
A9: Маркетинговий відділ | B9: 35.076923 | D9: Маркетинговий відділ | E9: 13 | F9: 8 | G9: 5
A10: Фінансовий відділ | B10: 38.555556 | D10: Фінансовий відділ | E10: 18 | F10: 11 | G10: 7
A11: Юридичний відділ | B11: 39.416667 | D11: Юридичний відділ | E11: 12 | F11: 6 | G11: 6
A12: Загальний підсумок | B12: 39.49 | D12: Загальний підсумок | E12: 100 | F12: 61 | G12: 39
A15: Кількість з Пенсійний вік | B15: Позначки стовпців
A16: Позначки рядків | B16: жіноча | C16: чоловіча | D16: Загальний підсумок
A17: Бухгалтерія | B17: 6 | C17: 10 | D17: 16
A18: Відділ збуту | B18: 4 | C18: 8 | D18: 12
A19: Відділ кадрів | B19: 5 | C19: 4 | D19: 9
A20: Господарський відділ | B20: 3 | C20: 7 | D20: 10
A21: Дирекція | B21: 5 | C21: 5 | D21: 10
A22: Маркетинговий відділ | B22: 3 | C22: 10 | D22: 13
A23: Фінансовий відділ | B23: 9 | C23: 9 | D23: 18
A24: Юридичний відділ | B24: 4 | C24: 8 | D24: 12
A25: Загальний підсумок | B25: 39 | C25: 61 | D25: 100
A28: Середнє з Вік на момент прийому на роботу | E28: Кількість з Причина звільнення | G28: Середнє з Стаж
A29: 39.49 | E29: 61 | G29: 7.24
A32: Сума з Працює в даний момент
A33: 39
A35: Кількість з Стаж | B35: Позначки стовпців
A36: Позначки рядків | B36: 0-4р | C36: 10-15р | D36: 5-9р | E36: Загальний підсумок
A37: жіноча | B37: 10 | C37: 13 | D37: 16 | E37: 39
A38: чоловіча | B38: 16 | C38: 16 | D38: 29 | E38: 61
A39: Загальний підсумок | B39: 26 | C39: 29 | D39: 45 | E39: 100
B41: Позначки стовпців
B42: 0-4р | C42: 10-15р | D42: 5-9р | E42: Загальний підсумок
A43: Кількість з Стаж | B43: 26 | C43: 29 | D43: 45 | E43: 100

Sheet Дашборд
